Workbook
Name HPvalue: PROFICIENCYVALUES!$B$7
Name WeaponWS: PROFICIENCYVALUES!$B$17
Name CLASSNUMBERFINDER: PROFICIENCYVALUES!$A$24:$B$47
Name CLASSLIST: PROFICIENCYVALUES!$C$24:$E$47
Name Expert: PROFICIENCYVALUES!$B$4
Name CLASSPROFILEHEADERS: CLASSPROFILES!$A$2:$A$25
Name CLASSNAMEHEADERS: CLASSDATA!$F$3:$BA$3
Name RangeWeaponGroups: PROFICIENCYVALUES!$A$59:$A$75
Name CLASSPICKER: PROFICIENCYVALUES!$A$24:$A$47
Name RangeClassProfiles: PROFICIENCYVALUES!$A$51:$A$56
Name CLASSPROFILEDATA: CLASSPROFILES!$B$2:$G$25
Name SpellSlot: PROFICIENCYVALUES!$B$13
Name RangeSkillNames: PROFICIENCYVALUES!$A$86:$A$102
Name AlchemicalFormula: PROFICIENCYVALUES!$B$15
Name SkillFeat: PROFICIENCYVALUES!$B$9
Name Trained: PROFICIENCYVALUES!$B$3
Name CantripLearned: PROFICIENCYVALUES!$B$10
Name Master: PROFICIENCYVALUES!$B$5
Name RangeAbilityScores: PROFICIENCYVALUES!$A$78:$A$83
Name WeaponCS: PROFICIENCYVALUES!$B$16
Name CLASSFEATUREHEADERS: CLASSDATA!$A$5:$A$279
Name Untrained: PROFICIENCYVALUES!$B$2
Name ALLCLASSDATA: CLASSDATA!$F$5:$BA$279
Name Legendary: PROFICIENCYVALUES!$B$6
Name ProficiencyValues: PROFICIENCYVALUES!$A$2:$B$6
Name ArmorAS: PROFICIENCYVALUES!$B$19
Name SkillIncrease: PROFICIENCYVALUES!$B$8
Name SpellSlotS10: PROFICIENCYVALUES!$B$14
Name CantripSlot: PROFICIENCYVALUES!$B$11
Name SpellLearned: PROFICIENCYVALUES!$B$12
Name WeaponGWS: PROFICIENCYVALUES!$B$18
Name CLASSPROFILENAMES: CLASSPROFILES!$B$1:$G$1

Sheet Table of Contents and Version N
A2: BALANCED CORE SYSTEM
A3: https://www.reddit.com/r/OpenBCS/ | C3: Author: Lazarus Dark
A5: TABLE OF CONTENTS:
A6: Sheet Name/Link | C6: Sheet description
A7: PROFICIENCYVALUES | C7: These are the base point values of the BCS and some basic information, includes defined ranges to use in formulas throughout this document.
A8: CLASSPROFILES | C8: This is where class profile information is stored, it may be tweaked over time, these profiles are not set in stone but should also be very good starter points.
A9: CLASSDATA | C9: This is where the official classes are broken down into their point values.
A10: CLASSTOTALS | C10: Using filters, this sheet makes it easier to compare the values of the official classes (and even compare them to your custom class). DO NOT EDIT THIS SHEET. Only change values on the CLASSDATA sheet to see changes here.
A11: SPECIALCLASSDATA | C11: A sheet for random class data just for reference, such as class archetype values and eidolon proficiencies.
A12: Class-Archetype Values | C12: This sheet shows the breakdown where the class archetype values were derived for SPECIALCLASSDATA sheet.
A13: MinMax for Profiles-Design Guides | C13: This data was used to help create the Profile system and also includes various class design guidelines based on research and analysis.
A14: Profile Analysis | C14: This is a different way to look at the classtotals. Incomplete.
A15: Save Analysis | C15: Used to evaluate save progression across classes in detail.
A16: Original Save Analysis | C16: The original save evaluation, in a more condensed format which is still good for comparing saves in a different way.
A17: Original Classes Compared | C17: The earliest version of the BCS for comparing class abilities and proficiencies. It can still be useful for comparing classes in a different way.
A18: old CLASSTOTALS | C18: An earlier version of CLASSTOTALS, arranged a little differently, some may prefer this arrangement so it is left here for that reason.
A19: Ancestries (Incomplete) | B19: Incomplete | C19: Work-In-Progress: The BCS isn't just about Classes, its about all the core values. I have a "Core Theory" that a characters stats, including Ancestry, all make up one total character value. So it is necessary to evaluate the cost of an ancestry.
A20: DualClass Calculator | B20: (originally paid-only, now free!) | C20: This will allow you to see the total value of a dual class according to normal dual classing rules. You can also use this to calculate a dual class closer to 2100, though its almost impossible to get to 2100 for a dual class, at that point you are likely making more of a class-archetype than a dual class.
A21: Class Creator for mobile users | B21: Full functionality only available to BCSF Purchasers | C21: The BCS Class Creator form is very advanced and most mobile pdf readers do not support its many functions, therefore this sheet is provided for use on mobile devices that cannot use the form pdf. (The Chrome/Chrome OS pdf viewer supports all form features in testing except page three of the form, only Acrobat reader/pro on desktop supported all page three functions in testing).
A22: Experiments with Class-Archetypes | B22: Full functionality only available to BCSF Purchasers | C22: Experiment tabs are just that, experiments in using the BCS to create new things. This tab is all about creating a Class-Archetypes. It should not be taken as the only way or the right way, just an experiment in what might be one way.
A23: Levels 21-30 (alpha state) | B23: Full functionality only available to BCSF Purchasers | C23: This is only the beginning of trying to make "balanced" levels over 20. I don't want to go too far on this until the community has vetted some of the BCS, but this starter page uses the same principles already established in the BCS.
A24: Open Game License (OGL) | C24: OGL info for this entire document
A30: version | B30: final release date | C30: release notes
A31: 1 | B31: 44708 | C31: Initial public release.
A32: 1.1 | B32: 44772 | C32: made some notes, added CS to a couple classes where missing and rebalanced (they balanced better than before obviously)
A33: 1.2 | B33: 44781 | C33: decoded Psychic/Thaumaturge, update OGL for DA
A34: 1.3 | B34: 45137 | C34: added Kineticist Playtest and updated OGL for Playtest (which required a BCS version change) - added CRB 4th printing errata, especially for Alchemist and Clerics
A35: 1.4 | B35: in progress | C35: decoded final Kineticist, update OGL for RoE
A39: Glossary and terminology
A40: SPL# or S## | C40: Spell Slot level # (named spells use the format: [Spellname] Spell #) (C=Cantrip)
A41: LVL# or L## | C41: Character level
A42: ALC# | C42: Alchemy Level
A43: "Level n" vs "nth-Level" | C43: Character levels should be "Level 1 feature, Level 2 feat, etc" and spell levels should be "1st-Level slot, 2nd-Level cantrip, etc." This helps avoid confustion between character levels and spell levels.
A44: class-archetype | C44: using a hyphen helps distinguish "class-archetypes" from "archetypes for classes"
A45: "published classes" | C45: this refers to the classes which are broken down here which were used to reverse engineer the BCS values

Sheet PROFICIENCYVALUES
A1: PROFICIENCY | B1: VALUE OF PROF. | C1: CHANGING THESE VALUES WILL MAKE CHANGES ACROSS MANY TABS AND FORMULAS.
A2: Untrained | B2: 0
A3: Trained | B3: 10 | C3: For Advanced Weapons (group or full), they always stay one proficiency behind Unarmed/Simple/Martial. So, if you start at Trained in Advanced Full, you MUST start at Expert in Unarmed/Simple/Martial and pay the Expert cost. If you start at Trained in Advanced Group, you MUST start at Expert in Simple Limited/Martial Limited and pay the Expert cost. (Its possible that a custom class could get Unarmed Limited group proficiency for the Brawling Group, but that would be a very rare and specific class)
A4: Expert | B4: 50
A5: Master | B5: 110
A6: Legendary | B6: 190
A7: HP | B7: 10
A8: SkillIncrease | B8: 5
A9: SkillFeat | B9: 5
A10: CantripLearned | B10: 5
A11: CantripSlot | B11: 5
A12: SpellLearned | B12: 10
A13: SpellSlot | B13: 10
A14: SpellSlotS10 | B14: 190
A15: AlchemicalFormula | B15: 5
... A19: ArmorAS | B19: 50
A23: CLASSES | C23: CLASS | D23: KEYSCORE | E23: PROFILETYPE
A24: Champion | B24: 1 | C24: Champion | D24: {=INDEX(ALLCLASSDATA,MATCH("KEYABILITY",CLASSFEATUREHEADERS,0),MATCH(C24,CLASSNAMEHEADERS,0))} -> STR/DEX | E24: {=INDEX(ALLCLASSDATA,MATCH("ClassType",CLASSFEATUREHEADERS,0),MATCH(C24,CLASSNAMEHEADERS,0))} -> Soldier
A25: Monk | B25: 2 | C25: Monk | D25: {=INDEX(ALLCLASSDATA,MATCH("KEYABILITY",CLASSFEATUREHEADERS,0),MATCH(C25,CLASSNAMEHEADERS,0))} -> STR/DEX | E25: {=INDEX(ALLCLASSDATA,MATCH("ClassType",CLASSFEATUREHEADERS,0),MATCH(C25,CLASSNAMEHEADERS,0))} -> Skirmisher
A26: Fighter | B26: 3 | C26: Fighter | D26: {=INDEX(ALLCLASSDATA,MATCH("KEYABILITY",CLASSFEATUREHEADERS,0),MATCH(C26,CLASSNAMEHEADERS,0))} -> STR/DEX | E26: {=INDEX(ALLCLASSDATA,MATCH("ClassType",CLASSFEATUREHEADERS,0),MATCH(C26,CLASSNAMEHEADERS,0))} -> Soldier
A27: Barbarian | B27: 4 | C27: Barbarian | D27: {=INDEX(ALLCLASSDATA,MATCH("KEYABILITY",CLASSFEATUREHEADERS,0),MATCH(C27,CLASSNAMEHEADERS,0))} -> STR | E27: {=INDEX(ALLCLASSDATA,MATCH("ClassType",CLASSFEATUREHEADERS,0),MATCH(C27,CLASSNAMEHEADERS,0))} -> Brute
A28: Ranger | B28: 5 | C28: Ranger | D28: {=INDEX(ALLCLASSDATA,MATCH("KEYABILITY",CLASSFEATUREHEADERS,0),MATCH(C28,CLASSNAMEHEADERS,0))} -> STR/DEX | E28: {=INDEX(ALLCLASSDATA,MATCH("ClassType",CLASSFEATUREHEADERS,0),MATCH(C28,CLASSNAMEHEADERS,0))} -> Sniper
A29: Rogue | B29: 6 | C29: Rogue | D29: {=INDEX(ALLCLASSDATA,MATCH("KEYABILITY",CLASSFEATUREHEADERS,0),MATCH(C29,CLASSNAMEHEADERS,0))} -> DEX* | E29: {=INDEX(ALLCLASSDATA,MATCH("ClassType",CLASSFEATUREHEADERS,0),MATCH(C29,CLASSNAMEHEADERS,0))} -> Skill Paragon
A30: Investigator | B30: 7 | C30: Investigator | D30: {=INDEX(ALLCLASSDATA,MATCH("KEYABILITY",CLASSFEATUREHEADERS,0),MATCH(C30,CLASSNAMEHEADERS,0))} -> INT | E30: {=INDEX(ALLCLASSDATA,MATCH("ClassType",CLASSFEATUREHEADERS,0),MATCH(C30,CLASSNAMEHEADERS,0))} -> Skirmisher
A31: Thaumaturge | B31: 8 | C31: Thaumaturge | D31: {=INDEX(ALLCLASSDATA,MATCH("KEYABILITY",CLASSFEATUREHEADERS,0),MATCH(C31,CLASSNAMEHEADERS,0))} -> CHA | E31: {=INDEX(ALLCLASSDATA,MATCH("ClassType",CLASSFEATUREHEADERS,0),MATCH(C31,CLASSNAMEHEADERS,0))} -> Skill Paragon
A32: Swashbuckler | B32: 9 | C32: Swashbuckler | D32: {=INDEX(ALLCLASSDATA,MATCH("KEYABILITY",CLASSFEATUREHEADERS,0),MATCH(C32,CLASSNAMEHEADERS,0))} -> DEX | E32: {=INDEX(ALLCLASSDATA,MATCH("ClassType",CLASSFEATUREHEADERS,0),MATCH(C32,CLASSNAMEHEADERS,0))} -> Skill Paragon
A33: Gunslinger | B33: 10 | C33: Gunslinger | D33: {=INDEX(ALLCLASSDATA,MATCH("KEYABILITY",CLASSFEATUREHEADERS,0),MATCH(C33,CLASSNAMEHEADERS,0))} -> DEX | E33: {=INDEX(ALLCLASSDATA,MATCH("ClassType",CLASSFEATUREHEADERS,0),MATCH(C33,CLASSNAMEHEADERS,0))} -> Sniper
A34: Inventor | B34: 11 | C34: Inventor | D34: {=INDEX(ALLCLASSDATA,MATCH("KEYABILITY",CLASSFEATUREHEADERS,0),MATCH(C34,CLASSNAMEHEADERS,0))} -> INT | E34: {=INDEX(ALLCLASSDATA,MATCH("ClassType",CLASSFEATUREHEADERS,0),MATCH(C34,CLASSNAMEHEADERS,0))} -> Brute
A35: Alchemist | B35: 12 | C35: Alchemist | D35: {=INDEX(ALLCLASSDATA,MATCH("KEYABILITY",CLASSFEATUREHEADERS,0),MATCH(C35,CLASSNAMEHEADERS,0))} -> INT | E35: {=INDEX(ALLCLASSDATA,MATCH("ClassType",CLASSFEATUREHEADERS,0),MATCH(C35,CLASSNAMEHEADERS,0))} -> Brute
... A47: ptKineticist | B47: 24 | C47: ptKineticist | D47: {=INDEX(ALLCLASSDATA,MATCH("KEYABILITY",CLASSFEATUREHEADERS,0),MATCH(C47,CLASSNAMEHEADERS,0))} -> #N/A | E47: {=INDEX(ALLCLASSDATA,MATCH("ClassType",CLASSFEATUREHEADERS,0),MATCH(C47,CLASSNAMEHEADERS,0))} -> #N/A
A50: ClassProfiles:
A51: Martial
A52: Martial-Skilled
A53: Martial-Specialist
A54: Martial-Caster
A55: Caster-Specialist
A56: Caster
A58: Weapon Groups
A59: Axe
A60: Bomb
...

Sheet CLASSPROFILES
B1: Martial | C1: Martial-Skilled | D1: Martial-Specialist | E1: Martial-Caster | F1: Caster-Specialist | G1: Caster
A2: HP | B2: 10 (max 12) | C2: 8 (max 10) | D2: 8 (max 10) | E2: 8 (max 10) | F2: 8 HP | G2: 6 HP
A3: PerceptionExpert | B3: L11 | C3: L01 | D3: L13 | E3: L09 | F3: L11 | G3: L11
A4: PerceptionMaster | C4: L07
A5: PerceptionLegendary | C5: L13
A6: FortitudeExpert | B6: L01 | C6: L09 | D6: L01 | E6: L01 | F6: L09 | G6: L09
A7: FortitudeMaster | B7: L09 | D7: L17 | E7: L15
A8: FortitudeLegendary
A9: ReflexExpert | B9: L09 | C9: L01 | D9: L07 | E9: L11 | F9: L13 | G9: L09
A10: ReflexMaster | C10: L07
A11: ReflexLegendary | C11: L13
A12: WillExpert | B12: L03 | C12: L03 | D12: L07 | E12: L01 | F12: L01 | G12: L01
A13: WillMaster | E13: L15 | F13: L11 | G13: L17
A14: WillLegendary
A15: WeaponRecommendation | B15: Martial | C15: Martial | D15: Martial | E15: Martial | F15: Simple | G15: Simple
A16: WeaponExpert | B16: L05 | C16: L05 | D16: L05 | E16: L05 | F16: L11 | G16: L11
A17: WeaponMaster | B17: L13 | C17: L13 | D17: L13 | E17: L13
A18: WeaponLegendary
A19: ArmorRecommendation | B19: Medium | C19: Light | D19: Light | E19: Medium | F19: Light | G19: Unarmored
A20: ArmorExpert | B20: L13 | C20: L13 | D20: L13 | E20: L11 | F20: L13 | G20: L13
A21: ArmorMaster | B21: L19 | C21: L19 | D21: L19 | E21: L17
A22: ArmorLegendary
A23: DCExpert | B23: L09 | C23: L09 | D23: L09 | E23: L09 | F23: L07 | G23: L07
A24: DCMaster | B24: L17 | C24: L17 | D24: L17 | E24: L17 | F24: L15 | G24: L15
A25: DCLegendary | F25: L19 | G25: L19
A28: Profiles are not rigid, they are more like suggestions. They are not part of the reverse engineered published classes, but something created and layered on top in order to help categorize classes (very loosely) and to make new class creation streamlined by simply selecting a profile to get your new class started without having to figure out every proficiency before you begin designing a class.
A29: Profiles were determined through analysis on the ProfileAnalysis tab. Mostly by grouping HP, proficiencies and class commonalities
A30: • MARTIAL: Standard martial classes usually start with 10 HP (all other profiles except Caster start with 8 HP) and are largely focused on high damage attacks and occasionally high defenses.
A31: • MARTIAL-SKILLED: The skilled martials often have Legendary Perception and Reflex in addition to extra skill increases or skill feats.
A32: • MARTIAL-SPECIALIST: These tend to specialize in one particular area such as one type of weapon or one type of fighting style.
A33: • MARTIAL-CASTER: These hybrid martials and casters have bounded casting and usually have more Attack proficiency and/or Defense proficiency than full casters.
A34: • CASTER-SPECIALIST: These full casters have a little more variance in their theme or abilities beyond just casting spells.
A35: • CASTER: Standard full casters have 6 HP and are more directly focused on being a powerful caster of spells.

Sheet CLASSDATA
A1: WARNING, DON'T CHANGE ANYTHING OTHER THAN POINT VALUES! DON'T RENAME COLUMN OR ROW HEADERS, YOU WILL BREAK EVERYTHING! | P1: colorcode: | T1: reasonable but not totally certain | X1: blue is total guess, needs verifying | AB1: yellow is questionable | AG1: Errata | AS1: currently working on some new balancing concepts, so Druid numbers are a little off right now
D2: CLASS | E2: PTS | F2: CLASS | G2: PTS | H2: CLASS | I2: PTS | J2: CLASS | K2: PTS | L2: CLASS | M2: PTS | N2: CLASS | O2: PTS | P2: CLASS | Q2: PTS | R2: CLASS | S2: PTS | T2: CLASS | U2: PTS | V2: CLASS | W2: PTS | X2: CLASS | Y2: PTS | Z2: CLASS | AA2: PTS | AB2: CLASS | AC2: PTS | AD2: CLASS | AE2: PTS | AF2: CLASS | AG2: PTS | AH2: CLASS | AI2: PTS | AJ2: CLASS | AK2: PTS | AL2: CLASS | AM2: PTS | AN2: CLASS | AO2: PTS | AP2: CLASS | AQ2: PTS | AR2: CLASS | AS2: PTS | AT2: CLASS | AU2: PTS | AV2: CLASS | AW2: PTS | AX2: CLASS | AY2: PTS | AZ2: CLASS | BA2: PTS
A3: CLASS----> | B3: LVL | C3: SPL | D3: TESTCLASS | E3: TESTPOINTS | F3: Champion | G3: ChampionPoints | H3: Monk | I3: MonkPoints | J3: Fighter | K3: FighterPoints | L3: Barbarian | M3: BarbarianPoints | N3: Ranger | O3: RangerPoints | P3: Rogue | Q3: RoguePoints | R3: Investigator | S3: InvestigatorPoints | T3: Thaumaturge | U3: ThaumaturgePoints | V3: Swashbuckler | W3: SwashbucklerPoints | X3: Gunslinger | Y3: GunslingerPoints | Z3: Inventor | AA3: InventorPoints | AB3: Alchemist | AC3: AlchemistPoints | AD3: Kineticist | AE3: KineticistPoints | AF3: Summoner | AG3: SummonerPoints | AH3: Magus | AI3: MagusPoints | AJ3: Cleric Warpriest | AK3: Cleric WarpriestPoints | AL3: Cleric Cloistered | AM3: Cleric CloisteredPoints | AN3: Bard | AO3: BardPoints | AP3: Oracle | AQ3: OraclePoints | AR3: Druid | AS3: DruidPoints | AT3: Psychic | AU3: PsychicPoints | AV3: Wizard | AW3: WizardPoints | AX3: Witch | AY3: WitchPoints | AZ3: Sorcerer | BA3: SorcererPoints
A4: BALANCETOTAL: | E4: =SUM(E5:E11)+E12+E21+E39+E26+E101+E133+E151+E154+E175+E196+E203+E250 -> 6870 | G4: =SUM(G5:G11)+G12+G21+G39+G26+G101+G133+G151+G154+G175+G196+G203+G250 -> 2100 | I4: =SUM(I5:I11)+I12+I21+I39+I26+I101+I133+I151+I154+I175+I196+I203+I250 -> 2100 | K4: =SUM(K5:K11)+K12+K21+K39+K26+K101+K133+K151+K154+K175+K196+K203+K250 -> 2100 | M4: =SUM(M5:M11)+M12+M21+M39+M26+M101+M133+M151+M154+M175+M196+M203+M250 -> 2100 | O4: =SUM(O5:O11)+O12+O21+O39+O26+O101+O133+O151+O154+O175+O196+O203+O250 -> 2100 | Q4: =SUM(Q5:Q11)+Q12+Q21+Q39+Q26+Q101+Q133+Q151+Q154+Q175+Q196+Q203+Q250 -> 2100 | S4: =SUM(S5:S11)+S12+S21+S39+S26+S101+S133+S151+S154+S175+S196+S203+S250 -> 2100 | U4: =SUM(U5:U11)+U12+U21+U39+U26+U101+U133+U151+U154+U175+U196+U203+U250 -> 2100 | W4: =SUM(W5:W11)+W12+W21+W39+W26+W101+W133+W151+W154+W175+W196+W203+W250 -> 2100 | Y4: =SUM(Y5:Y11)+Y12+Y21+Y39+Y26+Y101+Y133+Y151+Y154+Y175+Y196+Y203+Y250 -> 2100 | AA4: =SUM(AA5:AA11)+AA12+AA21+AA39+AA26+AA101+AA133+AA151+AA154+AA175+AA196+AA203+AA250 -> 2100 | AC4: =SUM(AC5:AC11)+AC12+AC21+AC39+AC26+AC101+AC133+AC151+AC154+AC175+AC196+AC203+AC250 -> 2100 | AE4: =SUM(AE5:AE11)+AE12+AE21+AE39+AE26+AE101+AE133+AE151+AE154+AE175+AE196+AE203+AE250 -> 2100 | AG4: =SUM(AG5:AG11)+AG12+AG21+AG39+AG26+AG101+AG133+AG151+AG154+AG175+AG196+AG203+AG250 -> 2100 | AI4: =SUM(AI5:AI11)+AI12+AI21+AI39+AI26+AI101+AI133+AI151+AI154+AI175+AI196+AI203+AI250 -> 2100 | AK4: =SUM(AK5:AK11)+AK12+AK21+AK39+AK26+AK101+AK133+AK151+AK154+AK175+AK196+AK203+AK250 -> 2050 | AM4: =SUM(AM5:AM11)+AM12+AM21+AM39+AM26+AM101+AM133+AM151+AM154+AM175+AM196+AM203+AM250 -> 2100 | AO4: =SUM(AO5:AO11)+AO12+AO21+AO39+AO26+AO101+AO133+AO151+AO154+AO175+AO196+AO203+AO250 -> 2100 | AQ4: =SUM(AQ5:AQ11)+AQ12+AQ21+AQ39+AQ26+AQ101+AQ133+AQ151+AQ154+AQ175+AQ196+AQ203+AQ250 -> 2100 | AS4: =SUM(AS5:AS11)+AS12+AS21+AS39+AS26+AS101+AS133+AS151+AS154+AS175+AS196+AS203+AS250 -> 2080 | AU4: =SUM(AU5:AU11)+AU12+AU21+AU39+AU26+AU101+AU133+AU151+AU154+AU175+AU196+AU203+AU250 -> 2100 | AW4: =SUM(AW5:AW11)+AW12+AW21+AW39+AW26+AW101+AW133+AW151+AW154+AW175+AW196+AW203+AW250 -> 2100 | AY4: =SUM(AY5:AY11)+AY12+AY21+AY39+AY26+AY101+AY133+AY151+AY154+AY175+AY196+AY203+AY250 -> 2100 | BA4: =SUM(BA5:BA11)+BA12+BA21+BA39+BA26+BA101+BA133+BA151+BA154+BA175+BA196+BA203+BA250 -> 2100
A5: ClassType | B5: L00 | D5: Martial | F5: Soldier | H5: Skirmisher | J5: Soldier | L5: Brute | N5: Sniper | P5: Skill Paragon | R5: Skirmisher | T5: Skill Paragon | V5: Skill Paragon | X5: Sniper | Z5: Brute | AB5: Brute | AD5: Brute | AF5: Magical Striker | AH5: Magical Striker | AJ5: Magical Striker | AL5: Spellcaster | AN5: Spellcaster | AP5: Spellcaster | AR5: Spellcaster | AT5: Spellcaster | AV5: Spellcaster | AX5: Spellcaster | AZ5: Spellcaster
A6: KEYABILITY | B6: L00 | D6: STR | F6: STR/DEX | H6: STR/DEX | J6: STR/DEX | L6: STR | N6: STR/DEX | P6: DEX* | R6: INT | T6: CHA | V6: DEX | X6: DEX | Z6: INT | AB6: INT | AD6: CON | AF6: CHA | AH6: STR/DEX | AJ6: WIS | AL6: WIS | AN6: CHA | AP6: CHA | AR6: WIS | AT6: INT/CHA | AV6: INT | AX6: INT | AZ6: CHA
A7: HP | B7: L00 | D7: 6 | E7: =HPvalue*D7 -> 60 | F7: 10 | G7: =HPvalue*F7 -> 100 | H7: 10 | I7: =HPvalue*H7 -> 100 | J7: 10 | K7: =HPvalue*J7 -> 100 | L7: 12 | M7: =HPvalue*L7 -> 120 | N7: 10 | O7: =HPvalue*N7 -> 100 | P7: 8 | Q7: =HPvalue*P7 -> 80 | R7: 8 | S7: =HPvalue*R7 -> 80 | T7: 8 | U7: =HPvalue*T7 -> 80 | V7: 10 | W7: =HPvalue*V7 -> 100 | X7: 8 | Y7: =HPvalue*X7 -> 80 | Z7: 8 | AA7: =HPvalue*Z7 -> 80 | AB7: 8 | AC7: =HPvalue*AB7 -> 80 | AD7: 8 | AE7: =HPvalue*AD7 -> 80 | AF7: 10 | AG7: =HPvalue*AF7 -> 100 | AH7: 8 | AI7: =HPvalue*AH7 -> 80 | AJ7: 8 | AK7: =HPvalue*AJ7 -> 80 | AL7: 8 | AM7: =HPvalue*AL7 -> 80 | AN7: 8 | AO7: =HPvalue*AN7 -> 80 | AP7: 8 | AQ7: =HPvalue*AP7 -> 80 | AR7: 8 | AS7: =HPvalue*AR7 -> 80 | AT7: 6 | AU7: =HPvalue*AT7 -> 60 | AV7: 6 | AW7: =HPvalue*AV7 -> 60 | AX7: 6 | AY7: =HPvalue*AX7 -> 60 | AZ7: 6 | BA7: =HPvalue*AZ7 -> 60
A8: ClassFeatL01 | B8: L01 | D8: TRUE | E8: =If(D8=True,10,"") -> 10 | F8: TRUE | G8: =If(F8=True,10,"") -> 10 | H8: TRUE | I8: =If(H8=True,10,"") -> 10 | J8: TRUE | K8: =If(J8=True,10,"") -> 10 | L8: TRUE | M8: =If(L8=True,10,"") -> 10 | N8: TRUE | O8: =If(N8=True,10,"") -> 10 | P8: TRUE | Q8: =If(P8=True,10,"") -> 10 | R8: TRUE | S8: =If(R8=True,10,"") -> 10 | T8: TRUE | U8: =If(T8=True,10,"") -> 10 | V8: TRUE | W8: =If(V8=True,10,"") -> 10 | X8: TRUE | Y8: =If(X8=True,10,"") -> 10 | Z8: TRUE | AA8: =If(Z8=True,10,"") -> 10 | AB8: TRUE | AC8: =If(AB8=True,10,"") -> 10 | AD8: TRUE | AE8: =If(AD8=True,10,"") -> 10 | AF8: FALSE | AG8: =If(AF8=True,10,"") | AH8: FALSE | AI8: =If(AH8=True,10,"") | AJ8: FALSE | AK8: =If(AJ8=True,10,"") | AL8: TRUE | AM8: =If(AL8=True,10,"") -> 10 | AN8: TRUE | AO8: =If(AN8=True,10,"") -> 10 | AP8: FALSE | AQ8: =If(AP8=True,10,"") | AR8: TRUE | AS8: =If(AR8=True,10,"") -> 10 | AT8: FALSE | AU8: =If(AT8=True,10,"") | AV8: FALSE | AW8: =If(AV8=True,10,"") | AX8: FALSE | AY8: =If(AX8=True,10,"") | AZ8: FALSE | BA8: =If(AZ8=True,10,"")
A9: ShieldBlockL01 | B9: L01 | D9: TRUE | E9: =If(D9=True,10,"") -> 10 | F9: TRUE | G9: =If(F9=True,10,"") -> 10 | H9: FALSE | I9: =If(H9=True,10,"") | J9: TRUE | K9: =If(J9=True,10,"") -> 10 | L9: FALSE | M9: =If(L9=True,10,"") | N9: FALSE | O9: =If(N9=True,10,"") | P9: FALSE | Q9: =If(P9=True,10,"") | R9: FALSE | S9: =If(R9=True,10,"") | T9: FALSE | U9: =If(T9=True,10,"") | V9: FALSE | W9: =If(V9=True,10,"") | X9: FALSE | Y9: =If(X9=True,10,"") | Z9: TRUE | AA9: =If(Z9=True,10,"") -> 10 | AB9: FALSE | AC9: =If(AB9=True,10,"") | AD9: FALSE | AE9: =If(AD9=True,10,"") | AF9: FALSE | AG9: =If(AF9=True,10,"") | AH9: FALSE | AI9: =If(AH9=True,10,"") | AJ9: TRUE | AK9: =If(AJ9=True,10,"") -> 10 | AL9: FALSE | AM9: =If(AL9=True,10,"") | AN9: FALSE | AO9: =If(AN9=True,10,"") | AP9: FALSE | AQ9: =If(AP9=True,10,"") | AR9: TRUE | AS9: =If(AR9=True,10,"") -> 10 | AT9: FALSE | AU9: =If(AT9=True,10,"") | AV9: FALSE | AW9: =If(AV9=True,10,"") | AX9: FALSE | AY9: =If(AX9=True,10,"") | AZ9: FALSE | BA9: =If(AZ9=True,10,"")
A10: CasterType | AB10: Alchemy | AF10: Bounded Spontaneous | AH10: Bounded Prepared | AJ10: Prepared | AL10: Prepared | AN10: Spontaneous | AP10: Spontaneous | AR10: Prepared | AT10: Spontaneous | AV10: Prepared | AX10: Prepared | AZ10: Spontaneous
A11: SpellList | AF11: Subclass List | AH11: Arcane | AJ11: Divine (Full List) | AL11: Divine (Full List) | AN11: Occult | AP11: Divine | AR11: Primal (Full List) | AT11: Occult | AV11: Arcane | AX11: Subclass List | AZ11: Subclass List
A12: DC TOTAL: | E12: =sum(E13:E20) -> 720 | G12: =sum(G13:G20) -> 170 | I12: =sum(I13:I20) -> 170 | K12: =sum(K13:K20) -> 170 | M12: =sum(M13:M20) -> 170 | O12: =sum(O13:O20) -> 170 | Q12: =sum(Q13:Q20) -> 170 | S12: =sum(S13:S20) -> 170 | U12: =sum(U13:U20) -> 170 | W12: =sum(W13:W20) -> 170 | Y12: =sum(Y13:Y20) -> 170 | AA12: =sum(AA13:AA20) -> 170 | AC12: =sum(AC13:AC20) -> 170 | AE12: =sum(AE13:AE20) -> 360 | AG12: =sum(AG13:AG20) -> 170 | AI12: =sum(AI13:AI20) -> 170 | AK12: =sum(AK13:AK20) -> 170 | AM12: =sum(AM13:AM20) -> 360 | AO12: =sum(AO13:AO20) -> 360 | AQ12: =sum(AQ13:AQ20) -> 360 | AS12: =sum(AS13:AS20) -> 360 | AU12: =sum(AU13:AU20) -> 360 | AW12: =sum(AW13:AW20) -> 360 | AY12: =sum(AY13:AY20) -> 360 | BA12: =sum(BA13:BA20) -> 360
A13: ClassDCTrained | D13: 01 | E13: =IF((ISBLANK(D13)),"",Trained) -> 10 | F13: 01 | G13: =IF((ISBLANK(F13)),"",Trained) -> 10 | H13: 01 | I13: =IF((ISBLANK(H13)),"",Trained) -> 10 | J13: 01 | K13: =IF((ISBLANK(J13)),"",Trained) -> 10 | L13: 01 | M13: =IF((ISBLANK(L13)),"",Trained) -> 10 | N13: 01 | O13: =IF((ISBLANK(N13)),"",Trained) -> 10 | P13: 01 | Q13: =IF((ISBLANK(P13)),"",Trained) -> 10 | R13: 01 | S13: =IF((ISBLANK(R13)),"",Trained) -> 10 | T13: 01 | U13: =IF((ISBLANK(T13)),"",Trained) -> 10 | V13: 01 | W13: =IF((ISBLANK(V13)),"",Trained) -> 10 | X13: 01 | Y13: =IF((ISBLANK(X13)),"",Trained) -> 10 | Z13: 01 | AA13: =IF((ISBLANK(Z13)),"",Trained) -> 10 | AB13: 01 | AC13: =IF((ISBLANK(AB13)),"",Trained) -> 10 | AD13: 01 | AE13: =IF((ISBLANK(AD13)),"",Trained) -> 10 | AG13: =IF((ISBLANK(AF13)),"",Trained) | AI13: =IF((ISBLANK(AH13)),"",Trained) | AK13: =IF((ISBLANK(AJ13)),"",Trained) | AM13: =IF((ISBLANK(AL13)),"",Trained) | AO13: =IF((ISBLANK(AN13)),"",Trained) | AQ13: =IF((ISBLANK(AP13)),"",Trained) | AS13: =IF((ISBLANK(AR13)),"",Trained) | AU13: =IF((ISBLANK(AT13)),"",Trained) | AW13: =IF((ISBLANK(AV13)),"",Trained) | AY13: =IF((ISBLANK(AX13)),"",Trained) | BA13: =IF((ISBLANK(AZ13)),"",Trained)
A14: ClassDCExpert | D14: 03 | E14: =IF((ISBLANK(D14)),"",Expert) -> 50 | F14: 09 | G14: =IF((ISBLANK(F14)),"",Expert) -> 50 | H14: 09 | I14: =IF((ISBLANK(H14)),"",Expert) -> 50 | J14: 11 | K14: =IF((ISBLANK(J14)),"",Expert) -> 50 | L14: 11 | M14: =IF((ISBLANK(L14)),"",Expert) -> 50 | N14: 09 | O14: =IF((ISBLANK(N14)),"",Expert) -> 50 | P14: 11 | Q14: =IF((ISBLANK(P14)),"",Expert) -> 50 | R14: 11 | S14: =IF((ISBLANK(R14)),"",Expert) -> 50 | T14: 09 | U14: =IF((ISBLANK(T14)),"",Expert) -> 50 | V14: 09 | W14: =IF((ISBLANK(V14)),"",Expert) -> 50 | X14: 09 | Y14: =IF((ISBLANK(X14)),"",Expert) -> 50 | Z14: 09 | AA14: =IF((ISBLANK(Z14)),"",Expert) -> 50 | AB14: 09 | AC14: =IF((ISBLANK(AB14)),"",Expert) -> 50 | AD14: 07 | AE14: =IF((ISBLANK(AD14)),"",Expert) -> 50 | AG14: =IF((ISBLANK(AF14)),"",Expert) | AI14: =IF((ISBLANK(AH14)),"",Expert) | AK14: =IF((ISBLANK(AJ14)),"",Expert) | AM14: =IF((ISBLANK(AL14)),"",Expert) | AO14: =IF((ISBLANK(AN14)),"",Expert) | AQ14: =IF((ISBLANK(AP14)),"",Expert) | AS14: =IF((ISBLANK(AR14)),"",Expert) | AU14: =IF((ISBLANK(AT14)),"",Expert) | AW14: =IF((ISBLANK(AV14)),"",Expert) | AY14: =IF((ISBLANK(AX14)),"",Expert) | BA14: =IF((ISBLANK(AZ14)),"",Expert)
A15: ClassDCMaster | D15: 05 | E15: =IF((ISBLANK(D15)),"",Master) -> 110 | F15: 17 | G15: =IF((ISBLANK(F15)),"",Master) -> 110 | H15: 17 | I15: =IF((ISBLANK(H15)),"",Master) -> 110 | J15: 19 | K15: =IF((ISBLANK(J15)),"",Master) -> 110 | L15: 19 | M15: =IF((ISBLANK(L15)),"",Master) -> 110 | N15: 17 | O15: =IF((ISBLANK(N15)),"",Master) -> 110 | P15: 19 | Q15: =IF((ISBLANK(P15)),"",Master) -> 110 | R15: 19 | S15: =IF((ISBLANK(R15)),"",Master) -> 110 | T15: 17 | U15: =IF((ISBLANK(T15)),"",Master) -> 110 | V15: 19 | W15: =IF((ISBLANK(V15)),"",Master) -> 110 | X15: 17 | Y15: =IF((ISBLANK(X15)),"",Master) -> 110 | Z15: 17 | AA15: =IF((ISBLANK(Z15)),"",Master) -> 110 | AB15: 17 | AC15: =IF((ISBLANK(AB15)),"",Master) -> 110 | AD15: 15 | AE15: =IF((ISBLANK(AD15)),"",Master) -> 110 | AG15: =IF((ISBLANK(AF15)),"",Master) | AI15: =IF((ISBLANK(AH15)),"",Master) | AK15: =IF((ISBLANK(AJ15)),"",Master) | AM15: =IF((ISBLANK(AL15)),"",Master) | AO15: =IF((ISBLANK(AN15)),"",Master) | AQ15: =IF((ISBLANK(AP15)),"",Master) | AS15: =IF((ISBLANK(AR15)),"",Master) | AU15: =IF((ISBLANK(AT15)),"",Master) | AW15: =IF((ISBLANK(AV15)),"",Master) | AY15: =IF((ISBLANK(AX15)),"",Master) | BA15: =IF((ISBLANK(AZ15)),"",Master)
A16: ClassDCLegendary | D16: 07 | E16: =IF((ISBLANK(D16)),"",Legendary) -> 190 | G16: =IF((ISBLANK(F16)),"",Legendary) | I16: =IF((ISBLANK(H16)),"",Legendary) | K16: =IF((ISBLANK(J16)),"",Legendary) | M16: =IF((ISBLANK(L16)),"",Legendary) | O16: =IF((ISBLANK(N16)),"",Legendary) | Q16: =IF((ISBLANK(P16)),"",Legendary) | S16: =IF((ISBLANK(R16)),"",Legendary) | U16: =IF((ISBLANK(T16)),"",Legendary) | W16: =IF((ISBLANK(V16)),"",Legendary) | Y16: =IF((ISBLANK(X16)),"",Legendary) | AA16: =IF((ISBLANK(Z16)),"",Legendary) | AC16: =IF((ISBLANK(AB16)),"",Legendary) | AD16: 19 | AE16: =IF((ISBLANK(AD16)),"",Legendary) -> 190 | AG16: =IF((ISBLANK(AF16)),"",Legendary) | AI16: =IF((ISBLANK(AH16)),"",Legendary) | AK16: =IF((ISBLANK(AJ16)),"",Legendary) | AM16: =IF((ISBLANK(AL16)),"",Legendary) | AO16: =IF((ISBLANK(AN16)),"",Legendary) | AQ16: =IF((ISBLANK(AP16)),"",Legendary) | AS16: =IF((ISBLANK(AR16)),"",Legendary) | AU16: =IF((ISBLANK(AT16)),"",Legendary) | AW16: =IF((ISBLANK(AV16)),"",Legendary) | AY16: =IF((ISBLANK(AX16)),"",Legendary) | BA16: =IF((ISBLANK(AZ16)),"",Legendary)
A17: SpellDCTrained | D17: 01 | E17: =IF((ISBLANK(D17)),"",Trained) -> 10 | G17: =IF((ISBLANK(F17)),"",Trained) | I17: =IF((ISBLANK(H17)),"",Trained) | K17: =IF((ISBLANK(J17)),"",Trained) | M17: =IF((ISBLANK(L17)),"",Trained) | O17: =IF((ISBLANK(N17)),"",Trained) | Q17: =IF((ISBLANK(P17)),"",Trained) | S17: =IF((ISBLANK(R17)),"",Trained) | U17: =IF((ISBLANK(T17)),"",Trained) | W17: =IF((ISBLANK(V17)),"",Trained) | Y17: =IF((ISBLANK(X17)),"",Trained) | AA17: =IF((ISBLANK(Z17)),"",Trained) | AC17: =IF((ISBLANK(AB17)),"",Trained) | AE17: =IF((ISBLANK(AD17)),"",Trained) | AF17: 01 | AG17: =IF((ISBLANK(AF17)),"",Trained) -> 10 | AH17: 01 | AI17: =IF((ISBLANK(AH17)),"",Trained) -> 10 | AJ17: 01 | AK17: =IF((ISBLANK(AJ17)),"",Trained) -> 10 | AL17: 01 | AM17: =IF((ISBLANK(AL17)),"",Trained) -> 10 | AN17: 01 | AO17: =IF((ISBLANK(AN17)),"",Trained) -> 10 | AP17: 01 | AQ17: =IF((ISBLANK(AP17)),"",Trained) -> 10 | AR17: 01 | AS17: =IF((ISBLANK(AR17)),"",Trained) -> 10 | AT17: 01 | AU17: =IF((ISBLANK(AT17)),"",Trained) -> 10 | AV17: 01 | AW17: =IF((ISBLANK(AV17)),"",Trained) -> 10 | AX17: 01 | AY17: =IF((ISBLANK(AX17)),"",Trained) -> 10 | AZ17: 01 | BA17: =IF((ISBLANK(AZ17)),"",Trained) -> 10
A18: SpellDCExpert | D18: 03 | E18: =IF((ISBLANK(D18)),"",Expert) -> 50 | G18: =IF((ISBLANK(F18)),"",Expert) | I18: =IF((ISBLANK(H18)),"",Expert) | K18: =IF((ISBLANK(J18)),"",Expert) | M18: =IF((ISBLANK(L18)),"",Expert) | O18: =IF((ISBLANK(N18)),"",Expert) | Q18: =IF((ISBLANK(P18)),"",Expert) | S18: =IF((ISBLANK(R18)),"",Expert) | U18: =IF((ISBLANK(T18)),"",Expert) | W18: =IF((ISBLANK(V18)),"",Expert) | Y18: =IF((ISBLANK(X18)),"",Expert) | AA18: =IF((ISBLANK(Z18)),"",Expert) | AC18: =IF((ISBLANK(AB18)),"",Expert) | AE18: =IF((ISBLANK(AD18)),"",Expert) | AF18: 09 | AG18: =IF((ISBLANK(AF18)),"",Expert) -> 50 | AH18: 09 | AI18: =IF((ISBLANK(AH18)),"",Expert) -> 50 | AJ18: 11 | AK18: =IF((ISBLANK(AJ18)),"",Expert) -> 50 | AL18: 07 | AM18: =IF((ISBLANK(AL18)),"",Expert) -> 50 | AN18: 07 | AO18: =IF((ISBLANK(AN18)),"",Expert) -> 50 | AP18: 07 | AQ18: =IF((ISBLANK(AP18)),"",Expert) -> 50 | AR18: 07 | AS18: =IF((ISBLANK(AR18)),"",Expert) -> 50 | AT18: 07 | AU18: =IF((ISBLANK(AT18)),"",Expert) -> 50 | AV18: 07 | AW18: =IF((ISBLANK(AV18)),"",Expert) -> 50 | AX18: 07 | AY18: =IF((ISBLANK(AX18)),"",Expert) -> 50 | AZ18: 07 | BA18: =IF((ISBLANK(AZ18)),"",Expert) -> 50
A19: SpellDCMaster | D19: 05 | E19: =IF((ISBLANK(D19)),"",Master) -> 110 | G19: =IF((ISBLANK(F19)),"",Master) | I19: =IF((ISBLANK(H19)),"",Master) | K19: =IF((ISBLANK(J19)),"",Master) | M19: =IF((ISBLANK(L19)),"",Master) | O19: =IF((ISBLANK(N19)),"",Master) | Q19: =IF((ISBLANK(P19)),"",Master) | S19: =IF((ISBLANK(R19)),"",Master) | U19: =IF((ISBLANK(T19)),"",Master) | W19: =IF((ISBLANK(V19)),"",Master) | Y19: =IF((ISBLANK(X19)),"",Master) | AA19: =IF((ISBLANK(Z19)),"",Master) | AC19: =IF((ISBLANK(AB19)),"",Master) | AE19: =IF((ISBLANK(AD19)),"",Master) | AF19: 17 | AG19: =IF((ISBLANK(AF19)),"",Master) -> 110 | AH19: 17 | AI19: =IF((ISBLANK(AH19)),"",Master) -> 110 | AJ19: 19 | AK19: =IF((ISBLANK(AJ19)),"",Master) -> 110 | AL19: 15 | AM19: =IF((ISBLANK(AL19)),"",Master) -> 110 | AN19: 15 | AO19: =IF((ISBLANK(AN19)),"",Master) -> 110 | AP19: 15 | AQ19: =IF((ISBLANK(AP19)),"",Master) -> 110 | AR19: 15 | AS19: =IF((ISBLANK(AR19)),"",Master) -> 110 | AT19: 15 | AU19: =IF((ISBLANK(AT19)),"",Master) -> 110 | AV19: 15 | AW19: =IF((ISBLANK(AV19)),"",Master) -> 110 | AX19: 15 | AY19: =IF((ISBLANK(AX19)),"",Master) -> 110 | AZ19: 15 | BA19: =IF((ISBLANK(AZ19)),"",Master) -> 110
A20: SpellDCLegendary | D20: 07 | E20: =IF((ISBLANK(D20)),"",Legendary) -> 190 | G20: =IF((ISBLANK(F20)),"",Legendary) | I20: =IF((ISBLANK(H20)),"",Legendary) | K20: =IF((ISBLANK(J20)),"",Legendary) | M20: =IF((ISBLANK(L20)),"",Legendary) | O20: =IF((ISBLANK(N20)),"",Legendary) | Q20: =IF((ISBLANK(P20)),"",Legendary) | S20: =IF((ISBLANK(R20)),"",Legendary) | U20: =IF((ISBLANK(T20)),"",Legendary) | W20: =IF((ISBLANK(V20)),"",Legendary) | Y20: =IF((ISBLANK(X20)),"",Legendary) | AA20: =IF((ISBLANK(Z20)),"",Legendary) | AC20: =IF((ISBLANK(AB20)),"",Legendary) | AE20: =IF((ISBLANK(AD20)),"",Legendary) | AG20: =IF((ISBLANK(AF20)),"",Legendary) | AI20: =IF((ISBLANK(AH20)),"",Legendary) | AK20: =IF((ISBLANK(AJ20)),"",Legendary) | AL20: 19 | AM20: =IF((ISBLANK(AL20)),"",Legendary) -> 190 | AN20: 19 | AO20: =IF((ISBLANK(AN20)),"",Legendary) -> 190 | AP20: 19 | AQ20: =IF((ISBLANK(AP20)),"",Legendary) -> 190 | AR20: 19 | AS20: =IF((ISBLANK(AR20)),"",Legendary) -> 190 | AT20: 19 | AU20: =IF((ISBLANK(AT20)),"",Legendary) -> 190 | AV20: 19 | AW20: =IF((ISBLANK(AV20)),"",Legendary) -> 190 | AX20: 19 | AY20: =IF((ISBLANK(AX20)),"",Legendary) -> 190 | AZ20: 19 | BA20: =IF((ISBLANK(AZ20)),"",Legendary) -> 190
A21: PERCEPTION TOTAL: | E21: =sum(E22:E25) -> 360 | G21: =sum(G22:G25) -> 60 | I21: =sum(I22:I25) -> 60 | K21: =sum(K22:K25) -> 170 | M21: =sum(M22:M25) -> 170 | O21: =sum(O22:O25) -> 360 | Q21: =sum(Q22:Q25) -> 360 | S21: =sum(S22:S25) -> 360 | U21: =sum(U22:U25) -> 170 | W21: =sum(W22:W25) -> 170 | Y21: =sum(Y22:Y25) -> 360 | AA21: =sum(AA22:AA25) -> 60 | AC21: =sum(AC22:AC25) -> 60 | AE21: =sum(AE22:AE25) -> 60 | AG21: =sum(AG22:AG25) -> 60 | AI21: =sum(AI22:AI25) -> 60 | AK21: =sum(AK22:AK25) -> 60 | AM21: =sum(AM22:AM25) -> 60 | AO21: =sum(AO22:AO25) -> 170 | AQ21: =sum(AQ22:AQ25) -> 60 | AS21: =sum(AS22:AS25) -> 60 | AU21: =sum(AU22:AU25) -> 60 | AW21: =sum(AW22:AW25) -> 60 | AY21: =sum(AY22:AY25) -> 60 | BA21: =sum(BA22:BA25) -> 60
A22: PerceptionTrained | D22: 01 | E22: =IF((ISBLANK(D22)),"",Trained) -> 10 | F22: 01 | G22: =IF((ISBLANK(F22)),"",Trained) -> 10 | H22: 01 | I22: =IF((ISBLANK(H22)),"",Trained) -> 10 | J22: 00 | K22: =IF((ISBLANK(J22)),"",Trained) -> 10 | L22: 00 | M22: =IF((ISBLANK(L22)),"",Trained) -> 10 | N22: 00 | O22: =IF((ISBLANK(N22)),"",Trained) -> 10 | P22: 00 | Q22: =IF((ISBLANK(P22)),"",Trained) -> 10 | R22: 00 | S22: =IF((ISBLANK(R22)),"",Trained) -> 10 | T22: 00 | U22: =IF((ISBLANK(T22)),"",Trained) -> 10 | V22: 00 | W22: =IF((ISBLANK(V22)),"",Trained) -> 10 | X22: 00 | Y22: =IF((ISBLANK(X22)),"",Trained) -> 10 | Z22: 01 | AA22: =IF((ISBLANK(Z22)),"",Trained) -> 10 | AB22: 01 | AC22: =IF((ISBLANK(AB22)),"",Trained) -> 10 | AD22: 01 | AE22: =IF((ISBLANK(AD22)),"",Trained) -> 10 | AF22: 01 | AG22: =IF((ISBLANK(AF22)),"",Trained) -> 10 | AH22: 01 | AI22: =IF((ISBLANK(AH22)),"",Trained) -> 10 | AJ22: 01 | AK22: =IF((ISBLANK(AJ22)),"",Trained) -> 10 | AL22: 01 | AM22: =IF((ISBLANK(AL22)),"",Trained) -> 10 | AN22: 00 | AO22: =IF((ISBLANK(AN22)),"",Trained) -> 10 | AP22: 01 | AQ22: =IF((ISBLANK(AP22)),"",Trained) -> 10 | AR22: 01 | AS22: =IF((ISBLANK(AR22)),"",Trained) -> 10 | AT22: 01 | AU22: =IF((ISBLANK(AT22)),"",Trained) -> 10 | AV22: 01 | AW22: =IF((ISBLANK(AV22)),"",Trained) -> 10 | AX22: 01 | AY22: =IF((ISBLANK(AX22)),"",Trained) -> 10 | AZ22: 01 | BA22: =IF((ISBLANK(AZ22)),"",Trained) -> 10
A23: PerceptionExpert | D23: 03 | E23: =IF((ISBLANK(D23)),"",Expert) -> 50 | F23: 11 | G23: =IF((ISBLANK(F23)),"",Expert) -> 50 | H23: 05 | I23: =IF((ISBLANK(H23)),"",Expert) -> 50 | J23: 01 | K23: =IF((ISBLANK(J23)),"",Expert) -> 50 | L23: 01 | M23: =IF((ISBLANK(L23)),"",Expert) -> 50 | N23: 01 | O23: =IF((ISBLANK(N23)),"",Expert) -> 50 | P23: 01 | Q23: =IF((ISBLANK(P23)),"",Expert) -> 50 | R23: 01 | S23: =IF((ISBLANK(R23)),"",Expert) -> 50 | T23: 01 | U23: =IF((ISBLANK(T23)),"",Expert) -> 50 | V23: 01 | W23: =IF((ISBLANK(V23)),"",Expert) -> 50 | X23: 01 | Y23: =IF((ISBLANK(X23)),"",Expert) -> 50 | Z23: 13 | AA23: =IF((ISBLANK(Z23)),"",Expert) -> 50 | AB23: 09 | AC23: =IF((ISBLANK(AB23)),"",Expert) -> 50 | AD23: 09 | AE23: =IF((ISBLANK(AD23)),"",Expert) -> 50 | AF23: 03 | AG23: =IF((ISBLANK(AF23)),"",Expert) -> 50 | AH23: 09 | AI23: =IF((ISBLANK(AH23)),"",Expert) -> 50 | AJ23: 05 | AK23: =IF((ISBLANK(AJ23)),"",Expert) -> 50 | AL23: 05 | AM23: =IF((ISBLANK(AL23)),"",Expert) -> 50 | AN23: 01 | AO23: =IF((ISBLANK(AN23)),"",Expert) -> 50 | AP23: 11 | AQ23: =IF((ISBLANK(AP23)),"",Expert) -> 50 | AR23: 03 | AS23: =IF((ISBLANK(AR23)),"",Expert) -> 50 | AT23: 11 | AU23: =IF((ISBLANK(AT23)),"",Expert) -> 50 | AV23: 11 | AW23: =IF((ISBLANK(AV23)),"",Expert) -> 50 | AX23: 11 | AY23: =IF((ISBLANK(AX23)),"",Expert) -> 50 | AZ23: 11 | BA23: =IF((ISBLANK(AZ23)),"",Expert) -> 50
A24: PerceptionMaster | D24: 05 | E24: =IF((ISBLANK(D24)),"",Master) -> 110 | G24: =IF((ISBLANK(F24)),"",Master) | I24: =IF((ISBLANK(H24)),"",Master) | J24: 07 | K24: =IF((ISBLANK(J24)),"",Master) -> 110 | L24: 17 | M24: =IF((ISBLANK(L24)),"",Master) -> 110 | N24: 07 | O24: =IF((ISBLANK(N24)),"",Master) -> 110 | P24: 07 | Q24: =IF((ISBLANK(P24)),"",Master) -> 110 | R24: 07 | S24: =IF((ISBLANK(R24)),"",Master) -> 110 | T24: 09 | U24: =IF((ISBLANK(T24)),"",Master) -> 110 | V24: 11 | W24: =IF((ISBLANK(V24)),"",Master) -> 110 | X24: 07 | Y24: =IF((ISBLANK(X24)),"",Master) -> 110 | AA24: =IF((ISBLANK(Z24)),"",Master) | AC24: =IF((ISBLANK(AB24)),"",Master) | AE24: =IF((ISBLANK(AD24)),"",Master) | AG24: =IF((ISBLANK(AF24)),"",Master) | AI24: =IF((ISBLANK(AH24)),"",Master) | AK24: =IF((ISBLANK(AJ24)),"",Master) | AM24: =IF((ISBLANK(AL24)),"",Master) | AN24: 11 | AO24: =IF((ISBLANK(AN24)),"",Master) -> 110 | AQ24: =IF((ISBLANK(AP24)),"",Master) | AS24: =IF((ISBLANK(AR24)),"",Master) | AU24: =IF((ISBLANK(AT24)),"",Master) | AW24: =IF((ISBLANK(AV24)),"",Master) | AY24: =IF((ISBLANK(AX24)),"",Master) | BA24: =IF((ISBLANK(AZ24)),"",Master)
A25: PerceptionLegendary | D25: 07 | E25: =IF((ISBLANK(D25)),"",Legendary) -> 190 | G25: =IF((ISBLANK(F25)),"",Legendary) | I25: =IF((ISBLANK(H25)),"",Legendary) | K25: =IF((ISBLANK(J25)),"",Legendary) | M25: =IF((ISBLANK(L25)),"",Legendary) | N25: 15 | O25: =IF((ISBLANK(N25)),"",Legendary) -> 190 | P25: 13 | Q25: =IF((ISBLANK(P25)),"",Legendary) -> 190 | R25: 13 | S25: =IF((ISBLANK(R25)),"",Legendary) -> 190 | U25: =IF((ISBLANK(T25)),"",Legendary) | W25: =IF((ISBLANK(V25)),"",Legendary) | X25: 19 | Y25: =IF((ISBLANK(X25)),"",Legendary) -> 190 | AA25: =IF((ISBLANK(Z25)),"",Legendary) | AC25: =IF((ISBLANK(AB25)),"",Legendary) | AE25: =IF((ISBLANK(AD25)),"",Legendary) | AG25: =IF((ISBLANK(AF25)),"",Legendary) | AI25: =IF((ISBLANK(AH25)),"",Legendary) | AK25: =IF((ISBLANK(AJ25)),"",Legendary) | AM25: =IF((ISBLANK(AL25)),"",Legendary) | AO25: =IF((ISBLANK(AN25)),"",Legendary) | AQ25: =IF((ISBLANK(AP25)),"",Legendary) | AS25: =IF((ISBLANK(AR25)),"",Legendary) | AU25: =IF((ISBLANK(AT25)),"",Legendary) | AW25: =IF((ISBLANK(AV25)),"",Legendary) | AY25: =IF((ISBLANK(AX25)),"",Legendary) | BA25: =IF((ISBLANK(AZ25)),"",Legendary)
A26: SAVES TOTAL: | E26: =sum(E27:E38) -> 1080 | G26: =sum(G27:G38) -> 400 | I26: =sum(I27:I38) -> 180 | K26: =sum(K27:K38) -> 400 | M26: =sum(M27:M38) -> 590 | O26: =sum(O27:O38) -> 590 | Q26: =sum(Q27:Q38) -> 590 | S26: =sum(S27:S38) -> 590 | U26: =sum(U27:U38) -> 590 | W26: =sum(W27:W38) -> 590 | Y26: =sum(Y27:Y38) -> 400 | AA26: =sum(AA27:AA38) -> 400 | AC26: =sum(AC27:AC38) -> 400 | AE26: =sum(AE27:AE38) -> 590 | AG26: =sum(AG27:AG38) -> 400 | AI26: =sum(AI27:AI38) -> 400 | AK26: =sum(AK27:AK38) -> 400 | AM26: =sum(AM27:AM38) -> 290 | AO26: =sum(AO27:AO38) -> 480 | AQ26: =sum(AQ27:AQ38) -> 480 | AS26: =sum(AS27:AS38) -> 290 | AU26: =sum(AU27:AU38) -> 480 | AW26: =sum(AW27:AW38) -> 290 | AY26: =sum(AY27:AY38) -> 290 | BA26: =sum(BA27:BA38) -> 290
A27: FortitudeSaveTrained | D27: 01 | E27: =IF((ISBLANK(D27)),"",Trained) -> 10 | F27: 00 | G27: =IF((ISBLANK(F27)),"",Trained) -> 10 | H27: 00 | I27: =IF((ISBLANK(H27)),"",Trained) -> 10 | J27: 00 | K27: =IF((ISBLANK(J27)),"",Trained) -> 10 | L27: 00 | M27: =IF((ISBLANK(L27)),"",Trained) -> 10 | N27: 00 | O27: =IF((ISBLANK(N27)),"",Trained) -> 10 | P27: 01 | Q27: =IF((ISBLANK(P27)),"",Trained) -> 10 | R27: 01 | S27: =IF((ISBLANK(R27)),"",Trained) -> 10 | T27: 00 | U27: =IF((ISBLANK(T27)),"",Trained) -> 10 | V27: 01 | W27: =IF((ISBLANK(V27)),"",Trained) -> 10 | X27: 00 | Y27: =IF((ISBLANK(X27)),"",Trained) -> 10 | Z27: 00 | AA27: =IF((ISBLANK(Z27)),"",Trained) -> 10 | AB27: 00 | AC27: =IF((ISBLANK(AB27)),"",Trained) -> 10 | AD27: 00 | AE27: =IF((ISBLANK(AD27)),"",Trained) -> 10 | AF27: 00 | AG27: =IF((ISBLANK(AF27)),"",Trained) -> 10 | AH27: 00 | AI27: =IF((ISBLANK(AH27)),"",Trained) -> 10 | AJ27: 00 | AK27: =IF((ISBLANK(AJ27)),"",Trained) -> 10 | AL27: 01 | AM27: =IF((ISBLANK(AL27)),"",Trained) -> 10 | AN27: 01 | AO27: =IF((ISBLANK(AN27)),"",Trained) -> 10 | AP27: 01 | AQ27: =IF((ISBLANK(AP27)),"",Trained) -> 10 | AR27: 01 | AS27: =IF((ISBLANK(AR27)),"",Trained) -> 10 | AT27: 01 | AU27: =IF((ISBLANK(AT27)),"",Trained) -> 10 | AV27: 01 | AW27: =IF((ISBLANK(AV27)),"",Trained) -> 10 | AX27: 01 | AY27: =IF((ISBLANK(AX27)),"",Trained) -> 10 | AZ27: 01 | BA27: =IF((ISBLANK(AZ27)),"",Trained) -> 10
A28: FortitudeSaveExpert | D28: 03 | E28: =IF((ISBLANK(D28)),"",Expert) -> 50 | F28: 01 | G28: =IF((ISBLANK(F28)),"",Expert) -> 50 | H28: 01 | I28: =IF((ISBLANK(H28)),"",Expert) -> 50 | J28: 01 | K28: =IF((ISBLANK(J28)),"",Expert) -> 50 | L28: 01 | M28: =IF((ISBLANK(L28)),"",Expert) -> 50 | N28: 01 | O28: =IF((ISBLANK(N28)),"",Expert) -> 50 | P28: 09 | Q28: =IF((ISBLANK(P28)),"",Expert) -> 50 | R28: 09 | S28: =IF((ISBLANK(R28)),"",Expert) -> 50 | T28: 01 | U28: =IF((ISBLANK(T28)),"",Expert) -> 50 | V28: 03 | W28: =IF((ISBLANK(V28)),"",Expert) -> 50 | X28: 01 | Y28: =IF((ISBLANK(X28)),"",Expert) -> 50 | Z28: 01 | AA28: =IF((ISBLANK(Z28)),"",Expert) -> 50 | AB28: 01 | AC28: =IF((ISBLANK(AB28)),"",Expert) -> 50 | AD28: 01 | AE28: =IF((ISBLANK(AD28)),"",Expert) -> 50 | AF28: 01 | AG28: =IF((ISBLANK(AF28)),"",Expert) -> 50 | AH28: 01 | AI28: =IF((ISBLANK(AH28)),"",Expert) -> 50 | AJ28: 01 | AK28: =IF((ISBLANK(AJ28)),"",Expert) -> 50 | AL28: 03 | AM28: =IF((ISBLANK(AL28)),"",Expert) -> 50 | AN28: 09 | AO28: =IF((ISBLANK(AN28)),"",Expert) -> 50 | AP28: 09 | AQ28: =IF((ISBLANK(AP28)),"",Expert) -> 50 | AR28: 03 | AS28: =IF((ISBLANK(AR28)),"",Expert) -> 50 | AT28: 09 | AU28: =IF((ISBLANK(AT28)),"",Expert) -> 50 | AV28: 09 | AW28: =IF((ISBLANK(AV28)),"",Expert) -> 50 | AX28: 05 | AY28: =IF((ISBLANK(AX28)),"",Expert) -> 50 | AZ28: 05 | BA28: =IF((ISBLANK(AZ28)),"",Expert) -> 50
A29: FortitudeSaveMaster | D29: 05 | E29: =IF((ISBLANK(D29)),"",Master) -> 110 | F29: 09 | G29: =IF((ISBLANK(F29)),"",Master) -> 110 | H29: 07 | I29: C | J29: 09 | K29: =IF((ISBLANK(J29)),"",Master) -> 110 | L29: 07 | M29: =IF((ISBLANK(L29)),"",Master) -> 110 | N29: 11 | O29: =IF((ISBLANK(N29)),"",Master) -> 110 | Q29: =IF((ISBLANK(P29)),"",Master) | S29: =IF((ISBLANK(R29)),"",Master) | T29: 15 | U29: =IF((ISBLANK(T29)),"",Master) -> 110 | W29: =IF((ISBLANK(V29)),"",Master) | X29: 17 | Y29: =IF((ISBLANK(X29)),"",Master) -> 110 | Z29: 17 | AA29: =IF((ISBLANK(Z29)),"",Master) -> 110 | AB29: 11 | AC29: =IF((ISBLANK(AB29)),"",Master) -> 110 | AD29: 07 | AE29: =IF((ISBLANK(AD29)),"",Master) -> 110 | AF29: 11 | AG29: =IF((ISBLANK(AF29)),"",Master) -> 110 | AH29: 15 | AI29: =IF((ISBLANK(AH29)),"",Master) -> 110 | AJ29: 15 | AK29: =IF((ISBLANK(AJ29)),"",Master) -> 110 | AM29: =IF((ISBLANK(AL29)),"",Master) | AO29: =IF((ISBLANK(AN29)),"",Master) | AQ29: =IF((ISBLANK(AP29)),"",Master) | AS29: =IF((ISBLANK(AR29)),"",Master) | AU29: =IF((ISBLANK(AT29)),"",Master) | AW29: =IF((ISBLANK(AV29)),"",Master) | AY29: =IF((ISBLANK(AX29)),"",Master) | BA29: =IF((ISBLANK(AZ29)),"",Master)
A30: FortitudeSaveLegendary | D30: 07 | E30: =IF((ISBLANK(D30)),"",Legendary) -> 190 | G30: =IF((ISBLANK(F30)),"",Legendary) | H30: 15 | I30: C | K30: =IF((ISBLANK(J30)),"",Legendary) | L30: 13 | M30: =IF((ISBLANK(L30)),"",Legendary) -> 190 | O30: =IF((ISBLANK(N30)),"",Legendary) | Q30: =IF((ISBLANK(P30)),"",Legendary) | S30: =IF((ISBLANK(R30)),"",Legendary) | U30: =IF((ISBLANK(T30)),"",Legendary) | W30: =IF((ISBLANK(V30)),"",Legendary) | Y30: =IF((ISBLANK(X30)),"",Legendary) | AA30: =IF((ISBLANK(Z30)),"",Legendary) | AC30: =IF((ISBLANK(AB30)),"",Legendary) | AD30: 15 | AE30: =IF((ISBLANK(AD30)),"",Legendary) -> 190 | AG30: =IF((ISBLANK(AF30)),"",Legendary) | AI30: =IF((ISBLANK(AH30)),"",Legendary) | AK30: =IF((ISBLANK(AJ30)),"",Legendary) | AM30: =IF((ISBLANK(AL30)),"",Legendary) | AO30: =IF((ISBLANK(AN30)),"",Legendary) | AQ30: =IF((ISBLANK(AP30)),"",Legendary) | AS30: =IF((ISBLANK(AR30)),"",Legendary) | AU30: =IF((ISBLANK(AT30)),"",Legendary) | AW30: =IF((ISBLANK(AV30)),"",Legendary) | AY30: =IF((ISBLANK(AX30)),"",Legendary) | BA30: =IF((ISBLANK(AZ30)),"",Legendary)
A31: ReflexSaveTrained | D31: 01 | E31: =IF((ISBLANK(D31)),"",Trained) -> 10 | F31: 01 | G31: =IF((ISBLANK(F31)),"",Trained) -> 10 | H31: 00 | I31: =IF((ISBLANK(H31)),"",Trained) -> 10 | J31: 00 | K31: =IF((ISBLANK(J31)),"",Trained) -> 10 | L31: 01 | M31: =IF((ISBLANK(L31)),"",Trained) -> 10 | N31: 00 | O31: =IF((ISBLANK(N31)),"",Trained) -> 10 | P31: 00 | Q31: =IF((ISBLANK(P31)),"",Trained) -> 10 | R31: 00 | S31: =IF((ISBLANK(R31)),"",Trained) -> 10 | T31: 01 | U31: =IF((ISBLANK(T31)),"",Trained) -> 10 | V31: 00 | W31: =IF((ISBLANK(V31)),"",Trained) -> 10 | X31: 00 | Y31: =IF((ISBLANK(X31)),"",Trained) -> 10 | Z31: 01 | AA31: =IF((ISBLANK(Z31)),"",Trained) -> 10 | AB31: 00 | AC31: =IF((ISBLANK(AB31)),"",Trained) -> 10 | AD31: 00 | AE31: =IF((ISBLANK(AD31)),"",Trained) -> 10 | AF31: 01 | AG31: =IF((ISBLANK(AF31)),"",Trained) -> 10 | AH31: 01 | AI31: =IF((ISBLANK(AH31)),"",Trained) -> 10 | AJ31: 01 | AK31: =IF((ISBLANK(AJ31)),"",Trained) -> 10 | AL31: 01 | AM31: =IF((ISBLANK(AL31)),"",Trained) -> 10 | AN31: 01 | AO31: =IF((ISBLANK(AN31)),"",Trained) -> 10 | AP31: 01 | AQ31: =IF((ISBLANK(AP31)),"",Trained) -> 10 | AR31: 01 | AS31: =IF((ISBLANK(AR31)),"",Trained) -> 10 | AT31: 01 | AU31: =IF((ISBLANK(AT31)),"",Trained) -> 10 | AV31: 01 | AW31: =IF((ISBLANK(AV31)),"",Trained) -> 10 | AX31: 01 | AY31: =IF((ISBLANK(AX31)),"",Trained) -> 10 | AZ31: 01 | BA31: =IF((ISBLANK(AZ31)),"",Trained) -> 10
A32: ReflexSaveExpert | D32: 03 | E32: =IF((ISBLANK(D32)),"",Expert) -> 50 | F32: 09 | G32: =IF((ISBLANK(F32)),"",Expert) -> 50 | H32: 01 | I32: =IF((ISBLANK(H32)),"",Expert) -> 50 | J32: 01 | K32: =IF((ISBLANK(J32)),"",Expert) -> 50 | L32: 09 | M32: =IF((ISBLANK(L32)),"",Expert) -> 50 | N32: 01 | O32: =IF((ISBLANK(N32)),"",Expert) -> 50 | P32: 01 | Q32: =IF((ISBLANK(P32)),"",Expert) -> 50 | R32: 01 | S32: =IF((ISBLANK(R32)),"",Expert) -> 50 | T32: 03 | U32: =IF((ISBLANK(T32)),"",Expert) -> 50 | V32: 01 | W32: =IF((ISBLANK(V32)),"",Expert) -> 50 | X32: 01 | Y32: =IF((ISBLANK(X32)),"",Expert) -> 50 | Z32: 07 | AA32: =IF((ISBLANK(Z32)),"",Expert) -> 50 | AB32: 01 | AC32: =IF((ISBLANK(AB32)),"",Expert) -> 50 | AD32: 01 | AE32: =IF((ISBLANK(AD32)),"",Expert) -> 50 | AF32: 09 | AG32: =IF((ISBLANK(AF32)),"",Expert) -> 50 | AH32: 05 | AI32: =IF((ISBLANK(AH32)),"",Expert) -> 50 | AJ32: 11 | AK32: =IF((ISBLANK(AJ32)),"",Expert) -> 50 | AL32: 11 | AM32: =IF((ISBLANK(AL32)),"",Expert) -> 50 | AN32: 03 | AO32: =IF((ISBLANK(AN32)),"",Expert) -> 50 | AP32: 13 | AQ32: =IF((ISBLANK(AP32)),"",Expert) -> 50 | AR32: 05 | AS32: =IF((ISBLANK(AR32)),"",Expert) -> 50 | AT32: 05 | AU32: =IF((ISBLANK(AT32)),"",Expert) -> 50 | AV32: 05 | AW32: =IF((ISBLANK(AV32)),"",Expert) -> 50 | AX32: 09 | AY32: =IF((ISBLANK(AX32)),"",Expert) -> 50 | AZ32: 09 | BA32: =IF((ISBLANK(AZ32)),"",Expert) -> 50
A33: ReflexSaveMaster | D33: 05 | E33: =IF((ISBLANK(D33)),"",Master) -> 110 | G33: =IF((ISBLANK(F33)),"",Master) | H33: 07 | I33: C | J33: 15 | K33: =IF((ISBLANK(J33)),"",Master) -> 110 | M33: =IF((ISBLANK(L33)),"",Master) | N33: 07 | O33: =IF((ISBLANK(N33)),"",Master) -> 110 | P33: 07 | Q33: =IF((ISBLANK(P33)),"",Master) -> 110 | R33: 15 | S33: =IF((ISBLANK(R33)),"",Master) -> 110 | U33: =IF((ISBLANK(T33)),"",Master) | V33: 07 | W33: =IF((ISBLANK(V33)),"",Master) -> 110 | X33: 11 | Y33: =IF((ISBLANK(X33)),"",Master) -> 110 | AA33: =IF((ISBLANK(Z33)),"",Master) | AB33: 15 | AC33: =IF((ISBLANK(AB33)),"",Master) -> 110 | AD33: 11 | AE33: =IF((ISBLANK(AD33)),"",Master) -> 110 | AG33: =IF((ISBLANK(AF33)),"",Master) | AI33: =IF((ISBLANK(AH33)),"",Master) | AK33: =IF((ISBLANK(AJ33)),"",Master) | AM33: =IF((ISBLANK(AL33)),"",Master) | AO33: =IF((ISBLANK(AN33)),"",Master) | AQ33: =IF((ISBLANK(AP33)),"",Master) | AS33: =IF((ISBLANK(AR33)),"",Master) | AU33: =IF((ISBLANK(AT33)),"",Master) | AW33: =IF((ISBLANK(AV33)),"",Master) | AY33: =IF((ISBLANK(AX33)),"",Master) | BA33: =IF((ISBLANK(AZ33)),"",Master)
A34: ReflexSaveLegendary | D34: 07 | E34: =IF((ISBLANK(D34)),"",Legendary) -> 190 | G34: =IF((ISBLANK(F34)),"",Legendary) | H34: 15 | I34: C | K34: =IF((ISBLANK(J34)),"",Legendary) | M34: =IF((ISBLANK(L34)),"",Legendary) | N34: 15 | O34: =IF((ISBLANK(N34)),"",Legendary) -> 190 | P34: 13 | Q34: =IF((ISBLANK(P34)),"",Legendary) -> 190 | S34: =IF((ISBLANK(R34)),"",Legendary) | U34: =IF((ISBLANK(T34)),"",Legendary) | V34: 13 | W34: =IF((ISBLANK(V34)),"",Legendary) -> 190 | Y34: =IF((ISBLANK(X34)),"",Legendary) | AA34: =IF((ISBLANK(Z34)),"",Legendary) | AC34: =IF((ISBLANK(AB34)),"",Legendary) | AE34: =IF((ISBLANK(AD34)),"",Legendary) | AG34: =IF((ISBLANK(AF34)),"",Legendary) | AI34: =IF((ISBLANK(AH34)),"",Legendary) | AK34: =IF((ISBLANK(AJ34)),"",Legendary) | AM34: =IF((ISBLANK(AL34)),"",Legendary) | AO34: =IF((ISBLANK(AN34)),"",Legendary) | AQ34: =IF((ISBLANK(AP34)),"",Legendary) | AS34: =IF((ISBLANK(AR34)),"",Legendary) | AU34: =IF((ISBLANK(AT34)),"",Legendary) | AW34: =IF((ISBLANK(AV34)),"",Legendary) | AY34: =IF((ISBLANK(AX34)),"",Legendary) | BA34: =IF((ISBLANK(AZ34)),"",Legendary)
A35: WillSaveTrained | D35: 01 | E35: =IF((ISBLANK(D35)),"",Trained) -> 10 | F35: 00 | G35: =IF((ISBLANK(F35)),"",Trained) -> 10 | H35: 00 | I35: =IF((ISBLANK(H35)),"",Trained) -> 10 | J35: 01 | K35: =IF((ISBLANK(J35)),"",Trained) -> 10 | L35: 00 | M35: =IF((ISBLANK(L35)),"",Trained) -> 10 | N35: 01 | O35: =IF((ISBLANK(N35)),"",Trained) -> 10 | P35: 00 | Q35: =IF((ISBLANK(P35)),"",Trained) -> 10 | R35: 00 | S35: =IF((ISBLANK(R35)),"",Trained) -> 10 | T35: 00 | U35: =IF((ISBLANK(T35)),"",Trained) -> 10 | V35: 00 | W35: =IF((ISBLANK(V35)),"",Trained) -> 10 | X35: 01 | Y35: =IF((ISBLANK(X35)),"",Trained) -> 10 | Z35: 00 | AA35: =IF((ISBLANK(Z35)),"",Trained) -> 10 | AB35: 01 | AC35: =IF((ISBLANK(AB35)),"",Trained) -> 10 | AD35: 01 | AE35: =IF((ISBLANK(AD35)),"",Trained) -> 10 | AF35: 00 | AG35: =IF((ISBLANK(AF35)),"",Trained) -> 10 | AH35: 00 | AI35: =IF((ISBLANK(AH35)),"",Trained) -> 10 | AJ35: 00 | AK35: =IF((ISBLANK(AJ35)),"",Trained) -> 10 | AL35: 00 | AM35: =IF((ISBLANK(AL35)),"",Trained) -> 10 | AN35: 00 | AO35: =IF((ISBLANK(AN35)),"",Trained) -> 10 | AP35: 00 | AQ35: =IF((ISBLANK(AP35)),"",Trained) -> 10 | AR35: 00 | AS35: =IF((ISBLANK(AR35)),"",Trained) -> 10 | AT35: 00 | AU35: =IF((ISBLANK(AT35)),"",Trained) -> 10 | AV35: 00 | AW35: =IF((ISBLANK(AV35)),"",Trained) -> 10 | AX35: 00 | AY35: =IF((ISBLANK(AX35)),"",Trained) -> 10 | AZ35: 00 | BA35: =IF((ISBLANK(AZ35)),"",Trained) -> 10
A36: WillSaveExpert | D36: 03 | E36: =IF((ISBLANK(D36)),"",Expert) -> 50 | F36: 01 | G36: =IF((ISBLANK(F36)),"",Expert) -> 50 | H36: 01 | I36: =IF((ISBLANK(H36)),"",Expert) -> 50 | J36: 03 | K36: =IF((ISBLANK(J36)),"",Expert) -> 50 | L36: 01 | M36: =IF((ISBLANK(L36)),"",Expert) -> 50 | N36: 03 | O36: =IF((ISBLANK(N36)),"",Expert) -> 50 | P36: 01 | Q36: =IF((ISBLANK(P36)),"",Expert) -> 50 | R36: 01 | S36: =IF((ISBLANK(R36)),"",Expert) -> 50 | T36: 01 | U36: =IF((ISBLANK(T36)),"",Expert) -> 50 | V36: 01 | W36: =IF((ISBLANK(V36)),"",Expert) -> 50 | X36: 03 | Y36: =IF((ISBLANK(X36)),"",Expert) -> 50 | Z36: 01 | AA36: =IF((ISBLANK(Z36)),"",Expert) -> 50 | AB36: 07 | AC36: =IF((ISBLANK(AB36)),"",Expert) -> 50 | AD36: 03 | AE36: =IF((ISBLANK(AD36)),"",Expert) -> 50 | AF36: 01 | AG36: =IF((ISBLANK(AF36)),"",Expert) -> 50 | AH36: 01 | AI36: =IF((ISBLANK(AH36)),"",Expert) -> 50 | AJ36: 01 | AK36: =IF((ISBLANK(AJ36)),"",Expert) -> 50 | AL36: 01 | AM36: =IF((ISBLANK(AL36)),"",Expert) -> 50 | AN36: 01 | AO36: =IF((ISBLANK(AN36)),"",Expert) -> 50 | AP36: 01 | AQ36: =IF((ISBLANK(AP36)),"",Expert) -> 50 | AR36: 01 | AS36: =IF((ISBLANK(AR36)),"",Expert) -> 50 | AT36: 01 | AU36: =IF((ISBLANK(AT36)),"",Expert) -> 50 | AV36: 01 | AW36: =IF((ISBLANK(AV36)),"",Expert) -> 50 | AX36: 01 | AY36: =IF((ISBLANK(AX36)),"",Expert) -> 50 | AZ36: 01 | BA36: =IF((ISBLANK(AZ36)),"",Expert) -> 50
A37: WillSaveMaster | D37: 05 | E37: =IF((ISBLANK(D37)),"",Master) -> 110 | F37: 11 | G37: =IF((ISBLANK(F37)),"",Master) -> 110 | H37: 07 | I37: C | K37: =IF((ISBLANK(J37)),"",Master) | L37: 15 | M37: =IF((ISBLANK(L37)),"",Master) -> 110 | O37: =IF((ISBLANK(N37)),"",Master) | P37: 17 | Q37: =IF((ISBLANK(P37)),"",Master) -> 110 | R37: 11 | S37: =IF((ISBLANK(R37)),"",Master) -> 110 | T37: 07 | U37: =IF((ISBLANK(T37)),"",Master) -> 110 | V37: 17 | W37: =IF((ISBLANK(V37)),"",Master) -> 110 | Y37: =IF((ISBLANK(X37)),"",Master) | Z37: 11 | AA37: =IF((ISBLANK(Z37)),"",Master) -> 110 | AC37: =IF((ISBLANK(AB37)),"",Master) | AE37: =IF((ISBLANK(AD37)),"",Master) | AF37: 15 | AG37: =IF((ISBLANK(AF37)),"",Master) -> 110 | AH37: 09 | AI37: =IF((ISBLANK(AH37)),"",Master) -> 110 | AJ37: 09 | AK37: =IF((ISBLANK(AJ37)),"",Master) -> 110 | AL37: 09 | AM37: =IF((ISBLANK(AL37)),"",Master) -> 110 | AN37: 09 | AO37: =IF((ISBLANK(AN37)),"",Master) -> 110 | AP37: 07 | AQ37: =IF((ISBLANK(AP37)),"",Master) -> 110 | AR37: 11 | AS37: =IF((ISBLANK(AR37)),"",Master) -> 110 | AT37: 11 | AU37: =IF((ISBLANK(AT37)),"",Master) -> 110 | AV37: 17 | AW37: =IF((ISBLANK(AV37)),"",Master) -> 110 | AX37: 17 | AY37: =IF((ISBLANK(AX37)),"",Master) -> 110 | AZ37: 17 | BA37: =IF((ISBLANK(AZ37)),"",Master) -> 110
A38: WillSaveLegendary | D38: 07 | E38: =IF((ISBLANK(D38)),"",Legendary) -> 190 | G38: =IF((ISBLANK(F38)),"",Legendary) | H38: 15 | I38: C | K38: =IF((ISBLANK(J38)),"",Legendary) | M38: =IF((ISBLANK(L38)),"",Legendary) | O38: =IF((ISBLANK(N38)),"",Legendary) | Q38: =IF((ISBLANK(P38)),"",Legendary) | R38: 17 | S38: =IF((ISBLANK(R38)),"",Legendary) -> 190 | T38: 13 | U38: =IF((ISBLANK(T38)),"",Legendary) -> 190 | W38: =IF((ISBLANK(V38)),"",Legendary) | Y38: =IF((ISBLANK(X38)),"",Legendary) | AA38: =IF((ISBLANK(Z38)),"",Legendary) | AC38: =IF((ISBLANK(AB38)),"",Legendary) | AE38: =IF((ISBLANK(AD38)),"",Legendary) | AG38: =IF((ISBLANK(AF38)),"",Legendary) | AI38: =IF((ISBLANK(AH38)),"",Legendary) | AK38: =IF((ISBLANK(AJ38)),"",Legendary) | AM38: =IF((ISBLANK(AL38)),"",Legendary) | AN38: 17 | AO38: =IF((ISBLANK(AN38)),"",Legendary) -> 190 | AP38: 17 | AQ38: =IF((ISBLANK(AP38)),"",Legendary) -> 190 | AS38: =IF((ISBLANK(AR38)),"",Legendary) | AT38: 17 | AU38: =IF((ISBLANK(AT38)),"",Legendary) -> 190 | AW38: =IF((ISBLANK(AV38)),"",Legendary) | AY38: =IF((ISBLANK(AX38)),"",Legendary) | BA38: =IF((ISBLANK(AZ38)),"",Legendary)
A39: SKILLS TOTAL: | E39: =E59+E79+E100 -> 290 | G39: =G59+G79+G100 -> 20 | I39: =I59+I79+I100 -> 20 | K39: =K59+K79+K100 -> 20 | M39: =M59+M79+M100 -> 20 | O39: =O59+O79+O100 -> 30 | Q39: =Q59+Q79+Q100 -> 140 | S39: =S59+S79+S100 -> 120 | U39: =U59+U79+U100 -> 70 | W39: =W59+W79+W100 -> 40 | Y39: =Y59+Y79+Y100 -> 20 | AA39: =AA59+AA79+AA100 -> 40 | AC39: =AC59+AC79+AC100 -> 20 | AE39: =AE59+AE79+AE100 -> 20 | AG39: =AG59+AG79+AG100 -> 25 | AI39: =AI59+AI79+AI100 -> 15 | AK39: =AK59+AK79+AK100 -> 20 | AM39: =AM59+AM79+AM100 -> 20 | AO39: =AO59+AO79+AO100 -> 30 | AQ39: =AQ59+AQ79+AQ100 -> 25 | AS39: =AS59+AS79+AS100 -> 20 | AU39: =AU59+AU79+AU100 -> 20 | AW39: =AW59+AW79+AW100 -> 15 | AY39: =AY59+AY79+AY100 -> 20 | BA39: =BA59+BA79+BA100 -> 20
A40: InitialSkillIncreases | B40: L00 | D40: 1 | E40: =D40*SkillIncrease -> 5 | F40: 2 | G40: =F40*SkillIncrease -> 10 | H40: 4 | I40: =H40*SkillIncrease -> 20 | J40: 3 | K40: =J40*SkillIncrease -> 15 | L40: 3 | M40: =L40*SkillIncrease -> 15 | N40: 4 | O40: =N40*SkillIncrease -> 20 | P40: 7 | Q40: =P40*SkillIncrease -> 35 | R40: 4 | S40: =R40*SkillIncrease -> 20 | T40: 3 | U40: =T40*SkillIncrease -> 15 | V40: 4 | W40: =V40*SkillIncrease -> 20 | X40: 3 | Y40: =X40*SkillIncrease -> 15 | Z40: 3 | AA40: =Z40*SkillIncrease -> 15 | AB40: 3 | AC40: =AB40*SkillIncrease -> 15 | AD40: 3 | AE40: =AD40*SkillIncrease -> 15 | AF40: 3 | AG40: =AF40*SkillIncrease -> 15 | AH40: 2 | AI40: =AH40*SkillIncrease -> 10 | AJ40: 2 | AK40: =AJ40*SkillIncrease -> 10 | AL40: 2 | AM40: =AL40*SkillIncrease -> 10 | AN40: 4 | AO40: =AN40*SkillIncrease -> 20 | AP40: 3 | AQ40: =AP40*SkillIncrease -> 15 | AR40: 2 | AS40: =AR40*SkillIncrease -> 10 | AT40: 3 | AU40: =AT40*SkillIncrease -> 15 | AV40: 2 | AW40: =AV40*SkillIncrease -> 10 | AX40: 3 | AY40: =AX40*SkillIncrease -> 15 | AZ40: 2 | BA40: =AZ40*SkillIncrease -> 10
...

Sheet CLASSTOTALS
A2: CLASS | D2: GROUP | E2: Proficiencies | F2: Initial Proficiency | G2: L00 | H2: 01 | I2: 02 | J2: 03 | K2: 04 | L2: 05 | M2: 06 | N2: 07 | O2: 08 | P2: 09 | Q2: 10 | R2: 11 | S2: 12 | T2: 13 | U2: 14 | V2: 15 | W2: 16 | X2: 17 | Y2: 18 | Z2: 19 | AA2: 20 | AB2: Final | AC2: Row Totals
A3: =VLOOKUP($C3, CLASSNUMBERFINDER, 2, false) -> 1 | C3: Champion
A4: {={"FormulaRow01";(INDEX(CLASSLIST,A3,1))}} -> FormulaRow01 | B4: FILTERFORMULAOUT | C4: {={"CLASSTYPE";(INDEX(ALLCLASSDATA,MATCH("ClassType",CLASSFEATUREHEADERS,0),MATCH($A5,CLASSNAMEHEADERS,0)))}} -> CLASSTYPE | D4: {={"TOTAL";("Total: " & H5+J5+L5+N5+P5+R5+T5+V5+X5+Z5)}} -> TOTAL | E4: {={"BALANCE";(IF((H5+J5+L5+N5+P5+R5+T5+V5+X5+Z5)=2100,"(balanced)",(IF((H5+J5+L5+N5+P5+R5+T5+V5+X5+Z5)>2100,"OVERBUDGET: ","UNDERBUDGET: ")) & (H5+J5+L5+N5+P5+R5+T5+V5+X5+Z5-2100)))}} -> BALANCE | H4: {={"SUM LVL0/1/2";((SUMIF(F6:I85,"<>#REF!")+(SUMIF(J6:AA13,"<>#REF!"))))}} -> SUM LVL0/1/2 | J4: {={"SUM LVL3/4";(SUMIF(J14:K85,"<>#REF!"))}} -> SUM LVL3/4 | L4: {={"SUM LVL5/6";(SUMIF(L14:M85,"<>#REF!"))}} -> SUM LVL5/6 | N4: {={"SUM LVL7/8";(SUMIF(N14:O85,"<>#REF!"))}} -> SUM LVL7/8 | P4: {={"SUM LVL9/10";(SUMIF(P14:Q85,"<>#REF!"))}} -> SUM LVL9/10 | R4: {={"SUM LVL11/12";(SUMIF(R14:S85,"<>#REF!"))}} -> SUM LVL11/12 | T4: {={"SUM LVL13/14";(SUMIF(T14:U85,"<>#REF!"))}} -> SUM LVL13/14 | V4: {={"SUM LVL15/16";(SUMIF(V14:W85,"<>#REF!"))}} -> SUM LVL15/16 | X4: {={"SUM LVL17/18";(SUMIF(X14:Y85,"<>#REF!"))}} -> SUM LVL17/18 | Z4: {={"SUM LVL19/20";(SUMIF(Z14:AA85,"<>#REF!"))}} -> SUM LVL19/20 | AC4: {={"SUM ROWTOTALS";(SUMIF(AC7:AC93,"<>#REF!"))}} -> SUM ROWTOTALS
A5: Champion | C5: Soldier | D5: Total: 2100 | E5: (balanced) | H5: 420 | J5: 30 | L5: 50 | N5: 170 | P5: 300 | R5: 270 | T5: 220 | V5: 150 | X5: 300 | Z5: 190 | AC5: 2100
